2014/01/18 18:03:34 - Error while retrieving btc_usd ticker
Traceback (most recent call last):
  File "/Library/Python/2.7/site-packages/btcebot/bot.py", line 100, in _ticker_loop
    response = btceapi.getTicker(p, conn)
  File "/Library/Python/2.7/site-packages/btceapi/public.py", line 50, in getTicker
    response = connection.makeJSONRequest("/api/2/%s/ticker" % pair)
  File "/Library/Python/2.7/site-packages/btceapi/common.py", line 118, in makeJSONRequest
    response = self.makeRequest(url, extra_headers, params)
  File "/Library/Python/2.7/site-packages/btceapi/common.py", line 113, in makeRequest
    response = self.conn.getresponse().read()
  File "/System/Library/Frameworks/Python.framework/Versions/2.7/lib/python2.7/httplib.py", line 1045, in getresponse
    response.begin()
  File "/System/Library/Frameworks/Python.framework/Versions/2.7/lib/python2.7/httplib.py", line 409, in begin
    version, status, reason = self._read_status()
  File "/System/Library/Frameworks/Python.framework/Versions/2.7/lib/python2.7/httplib.py", line 373, in _read_status
    raise BadStatusLine(line)
BadStatusLine: ''

--------------------------------------------------------------------------------
2014/01/18 18:03:34 - Error while retrieving ltc_btc ticker
Traceback (most recent call last):
  File "/Library/Python/2.7/site-packages/btcebot/bot.py", line 100, in _ticker_loop
    response = btceapi.getTicker(p, conn)
  File "/Library/Python/2.7/site-packages/btceapi/public.py", line 50, in getTicker
    response = connection.makeJSONRequest("/api/2/%s/ticker" % pair)
  File "/Library/Python/2.7/site-packages/btceapi/common.py", line 118, in makeJSONRequest
    response = self.makeRequest(url, extra_headers, params)
  File "/Library/Python/2.7/site-packages/btceapi/common.py", line 112, in makeRequest
    self.conn.request("POST", url, params, headers)
  File "/System/Library/Frameworks/Python.framework/Versions/2.7/lib/python2.7/httplib.py", line 973, in request
    self._send_request(method, url, body, headers)
  File "/System/Library/Frameworks/Python.framework/Versions/2.7/lib/python2.7/httplib.py", line 1001, in _send_request
    self.putrequest(method, url, **skips)
  File "/System/Library/Frameworks/Python.framework/Versions/2.7/lib/python2.7/httplib.py", line 871, in putrequest
    raise CannotSendRequest()
CannotSendRequest

--------------------------------------------------------------------------------
2014/01/18 18:03:34 - Error while retrieving ltc_rur ticker
Traceback (most recent call last):
  File "/Library/Python/2.7/site-packages/btcebot/bot.py", line 100, in _ticker_loop
    response = btceapi.getTicker(p, conn)
  File "/Library/Python/2.7/site-packages/btceapi/public.py", line 50, in getTicker
    response = connection.makeJSONRequest("/api/2/%s/ticker" % pair)
  File "/Library/Python/2.7/site-packages/btceapi/common.py", line 118, in makeJSONRequest
    response = self.makeRequest(url, extra_headers, params)
  File "/Library/Python/2.7/site-packages/btceapi/common.py", line 112, in makeRequest
    self.conn.request("POST", url, params, headers)
  File "/System/Library/Frameworks/Python.framework/Versions/2.7/lib/python2.7/httplib.py", line 973, in request
    self._send_request(method, url, body, headers)
  File "/System/Library/Frameworks/Python.framework/Versions/2.7/lib/python2.7/httplib.py", line 1001, in _send_request
    self.putrequest(method, url, **skips)
  File "/System/Library/Frameworks/Python.framework/Versions/2.7/lib/python2.7/httplib.py", line 871, in putrequest
    raise CannotSendRequest()
CannotSendRequest

--------------------------------------------------------------------------------
2014/01/18 18:03:34 - Error while retrieving ltc_usd ticker
Traceback (most recent call last):
  File "/Library/Python/2.7/site-packages/btcebot/bot.py", line 100, in _ticker_loop
    response = btceapi.getTicker(p, conn)
  File "/Library/Python/2.7/site-packages/btceapi/public.py", line 50, in getTicker
    response = connection.makeJSONRequest("/api/2/%s/ticker" % pair)
  File "/Library/Python/2.7/site-packages/btceapi/common.py", line 118, in makeJSONRequest
    response = self.makeRequest(url, extra_headers, params)
  File "/Library/Python/2.7/site-packages/btceapi/common.py", line 112, in makeRequest
    self.conn.request("POST", url, params, headers)
  File "/System/Library/Frameworks/Python.framework/Versions/2.7/lib/python2.7/httplib.py", line 973, in request
    self._send_request(method, url, body, headers)
  File "/System/Library/Frameworks/Python.framework/Versions/2.7/lib/python2.7/httplib.py", line 1001, in _send_request
    self.putrequest(method, url, **skips)
  File "/System/Library/Frameworks/Python.framework/Versions/2.7/lib/python2.7/httplib.py", line 871, in putrequest
    raise CannotSendRequest()
CannotSendRequest

--------------------------------------------------------------------------------
2014/01/18 18:03:34 - Error while retrieving btc_eur ticker
Traceback (most recent call last):
  File "/Library/Python/2.7/site-packages/btcebot/bot.py", line 100, in _ticker_loop
    response = btceapi.getTicker(p, conn)
  File "/Library/Python/2.7/site-packages/btceapi/public.py", line 50, in getTicker
    response = connection.makeJSONRequest("/api/2/%s/ticker" % pair)
  File "/Library/Python/2.7/site-packages/btceapi/common.py", line 118, in makeJSONRequest
    response = self.makeRequest(url, extra_headers, params)
  File "/Library/Python/2.7/site-packages/btceapi/common.py", line 112, in makeRequest
    self.conn.request("POST", url, params, headers)
  File "/System/Library/Frameworks/Python.framework/Versions/2.7/lib/python2.7/httplib.py", line 973, in request
    self._send_request(method, url, body, headers)
  File "/System/Library/Frameworks/Python.framework/Versions/2.7/lib/python2.7/httplib.py", line 1001, in _send_request
    self.putrequest(method, url, **skips)
  File "/System/Library/Frameworks/Python.framework/Versions/2.7/lib/python2.7/httplib.py", line 871, in putrequest
    raise CannotSendRequest()
CannotSendRequest

--------------------------------------------------------------------------------
2014/01/18 18:03:34 - Error while retrieving btc_rur ticker
Traceback (most recent call last):
  File "/Library/Python/2.7/site-packages/btcebot/bot.py", line 100, in _ticker_loop
    response = btceapi.getTicker(p, conn)
  File "/Library/Python/2.7/site-packages/btceapi/public.py", line 50, in getTicker
    response = connection.makeJSONRequest("/api/2/%s/ticker" % pair)
  File "/Library/Python/2.7/site-packages/btceapi/common.py", line 118, in makeJSONRequest
    response = self.makeRequest(url, extra_headers, params)
  File "/Library/Python/2.7/site-packages/btceapi/common.py", line 112, in makeRequest
    self.conn.request("POST", url, params, headers)
  File "/System/Library/Frameworks/Python.framework/Versions/2.7/lib/python2.7/httplib.py", line 973, in request
    self._send_request(method, url, body, headers)
  File "/System/Library/Frameworks/Python.framework/Versions/2.7/lib/python2.7/httplib.py", line 1001, in _send_request
    self.putrequest(method, url, **skips)
  File "/System/Library/Frameworks/Python.framework/Versions/2.7/lib/python2.7/httplib.py", line 871, in putrequest
    raise CannotSendRequest()
CannotSendRequest

--------------------------------------------------------------------------------
2014/01/18 18:03:34 - Error in handler <bound method TradeBot.onNewDepth of <__main__.TradeBot object at 0x10660b450>> for ltc_eur depth
Traceback (most recent call last):
  File "/Library/Python/2.7/site-packages/btcebot/bot.py", line 52, in _runBot
    handler(t, p, asks, bids)
  File "/Users/afansky/dev/code/bitcoin_bot/trade-bot/tradebot/tradebot.py", line 29, in onNewDepth
    self.analyzer.analyze(t, pair)
  File "/Users/afansky/dev/code/bitcoin_bot/trade-bot/tradebot/analysis/analysis.py", line 19, in analyze
    df = create_data_frame(ticks)
  File "/Users/afansky/dev/code/bitcoin_bot/trade-bot/tradebot/analysis/analysis.py", line 42, in create_data_frame
    return pd.DataFrame(ticks_new, columns=['high_price', 'low_price', 'avg_price', 'last_price', 'buy_price', 'sell_price', 'volume', 'current_volume'], index=index)
  File "/Library/Python/2.7/site-packages/pandas-0.12.0-py2.7-macosx-10.9-intel.egg/pandas/core/frame.py", line 434, in __init__
    copy=copy)
  File "/Library/Python/2.7/site-packages/pandas-0.12.0-py2.7-macosx-10.9-intel.egg/pandas/core/frame.py", line 561, in _init_ndarray
    return create_block_manager_from_blocks([ values.T ], [ columns, index ])
  File "/Library/Python/2.7/site-packages/pandas-0.12.0-py2.7-macosx-10.9-intel.egg/pandas/core/internals.py", line 2234, in create_block_manager_from_blocks
    construction_error(tot_items,blocks[0].shape[1:],axes)
  File "/Library/Python/2.7/site-packages/pandas-0.12.0-py2.7-macosx-10.9-intel.egg/pandas/core/internals.py", line 2216, in construction_error
    tuple(map(int, [len(ax) for ax in axes]))))
ValueError: Shape of passed values is (0, 0), indices imply (8, 0)

--------------------------------------------------------------------------------
2014/01/18 18:03:34 - Error in handler <bound method TradeBot.onNewDepth of <__main__.TradeBot object at 0x10660b450>> for btc_usd depth
Traceback (most recent call last):
  File "/Library/Python/2.7/site-packages/btcebot/bot.py", line 52, in _runBot
    handler(t, p, asks, bids)
  File "/Users/afansky/dev/code/bitcoin_bot/trade-bot/tradebot/tradebot.py", line 29, in onNewDepth
    self.analyzer.analyze(t, pair)
  File "/Users/afansky/dev/code/bitcoin_bot/trade-bot/tradebot/analysis/analysis.py", line 19, in analyze
    df = create_data_frame(ticks)
  File "/Users/afansky/dev/code/bitcoin_bot/trade-bot/tradebot/analysis/analysis.py", line 42, in create_data_frame
    return pd.DataFrame(ticks_new, columns=['high_price', 'low_price', 'avg_price', 'last_price', 'buy_price', 'sell_price', 'volume', 'current_volume'], index=index)
  File "/Library/Python/2.7/site-packages/pandas-0.12.0-py2.7-macosx-10.9-intel.egg/pandas/core/frame.py", line 434, in __init__
    copy=copy)
  File "/Library/Python/2.7/site-packages/pandas-0.12.0-py2.7-macosx-10.9-intel.egg/pandas/core/frame.py", line 561, in _init_ndarray
    return create_block_manager_from_blocks([ values.T ], [ columns, index ])
  File "/Library/Python/2.7/site-packages/pandas-0.12.0-py2.7-macosx-10.9-intel.egg/pandas/core/internals.py", line 2234, in create_block_manager_from_blocks
    construction_error(tot_items,blocks[0].shape[1:],axes)
  File "/Library/Python/2.7/site-packages/pandas-0.12.0-py2.7-macosx-10.9-intel.egg/pandas/core/internals.py", line 2216, in construction_error
    tuple(map(int, [len(ax) for ax in axes]))))
ValueError: Shape of passed values is (0, 0), indices imply (8, 0)

--------------------------------------------------------------------------------
2014/01/18 18:03:34 - Error in handler <bound method TradeBot.onNewDepth of <__main__.TradeBot object at 0x10660b450>> for ltc_btc depth
Traceback (most recent call last):
  File "/Library/Python/2.7/site-packages/btcebot/bot.py", line 52, in _runBot
    handler(t, p, asks, bids)
  File "/Users/afansky/dev/code/bitcoin_bot/trade-bot/tradebot/tradebot.py", line 29, in onNewDepth
    self.analyzer.analyze(t, pair)
  File "/Users/afansky/dev/code/bitcoin_bot/trade-bot/tradebot/analysis/analysis.py", line 19, in analyze
    df = create_data_frame(ticks)
  File "/Users/afansky/dev/code/bitcoin_bot/trade-bot/tradebot/analysis/analysis.py", line 42, in create_data_frame
    return pd.DataFrame(ticks_new, columns=['high_price', 'low_price', 'avg_price', 'last_price', 'buy_price', 'sell_price', 'volume', 'current_volume'], index=index)
  File "/Library/Python/2.7/site-packages/pandas-0.12.0-py2.7-macosx-10.9-intel.egg/pandas/core/frame.py", line 434, in __init__
    copy=copy)
  File "/Library/Python/2.7/site-packages/pandas-0.12.0-py2.7-macosx-10.9-intel.egg/pandas/core/frame.py", line 561, in _init_ndarray
    return create_block_manager_from_blocks([ values.T ], [ columns, index ])
  File "/Library/Python/2.7/site-packages/pandas-0.12.0-py2.7-macosx-10.9-intel.egg/pandas/core/internals.py", line 2234, in create_block_manager_from_blocks
    construction_error(tot_items,blocks[0].shape[1:],axes)
  File "/Library/Python/2.7/site-packages/pandas-0.12.0-py2.7-macosx-10.9-intel.egg/pandas/core/internals.py", line 2216, in construction_error
    tuple(map(int, [len(ax) for ax in axes]))))
ValueError: Shape of passed values is (0, 0), indices imply (8, 0)

--------------------------------------------------------------------------------
2014/01/18 18:03:34 - Error in handler <bound method TradeBot.onNewDepth of <__main__.TradeBot object at 0x10660b450>> for ltc_rur depth
Traceback (most recent call last):
  File "/Library/Python/2.7/site-packages/btcebot/bot.py", line 52, in _runBot
    handler(t, p, asks, bids)
  File "/Users/afansky/dev/code/bitcoin_bot/trade-bot/tradebot/tradebot.py", line 29, in onNewDepth
    self.analyzer.analyze(t, pair)
  File "/Users/afansky/dev/code/bitcoin_bot/trade-bot/tradebot/analysis/analysis.py", line 19, in analyze
    df = create_data_frame(ticks)
  File "/Users/afansky/dev/code/bitcoin_bot/trade-bot/tradebot/analysis/analysis.py", line 42, in create_data_frame
    return pd.DataFrame(ticks_new, columns=['high_price', 'low_price', 'avg_price', 'last_price', 'buy_price', 'sell_price', 'volume', 'current_volume'], index=index)
  File "/Library/Python/2.7/site-packages/pandas-0.12.0-py2.7-macosx-10.9-intel.egg/pandas/core/frame.py", line 434, in __init__
    copy=copy)
  File "/Library/Python/2.7/site-packages/pandas-0.12.0-py2.7-macosx-10.9-intel.egg/pandas/core/frame.py", line 561, in _init_ndarray
    return create_block_manager_from_blocks([ values.T ], [ columns, index ])
  File "/Library/Python/2.7/site-packages/pandas-0.12.0-py2.7-macosx-10.9-intel.egg/pandas/core/internals.py", line 2234, in create_block_manager_from_blocks
    construction_error(tot_items,blocks[0].shape[1:],axes)
  File "/Library/Python/2.7/site-packages/pandas-0.12.0-py2.7-macosx-10.9-intel.egg/pandas/core/internals.py", line 2216, in construction_error
    tuple(map(int, [len(ax) for ax in axes]))))
ValueError: Shape of passed values is (0, 0), indices imply (8, 0)

--------------------------------------------------------------------------------
2014/01/18 18:03:34 - Error in handler <bound method TradeBot.onNewDepth of <__main__.TradeBot object at 0x10660b450>> for ltc_usd depth
Traceback (most recent call last):
  File "/Library/Python/2.7/site-packages/btcebot/bot.py", line 52, in _runBot
    handler(t, p, asks, bids)
  File "/Users/afansky/dev/code/bitcoin_bot/trade-bot/tradebot/tradebot.py", line 29, in onNewDepth
    self.analyzer.analyze(t, pair)
  File "/Users/afansky/dev/code/bitcoin_bot/trade-bot/tradebot/analysis/analysis.py", line 19, in analyze
    df = create_data_frame(ticks)
  File "/Users/afansky/dev/code/bitcoin_bot/trade-bot/tradebot/analysis/analysis.py", line 42, in create_data_frame
    return pd.DataFrame(ticks_new, columns=['high_price', 'low_price', 'avg_price', 'last_price', 'buy_price', 'sell_price', 'volume', 'current_volume'], index=index)
  File "/Library/Python/2.7/site-packages/pandas-0.12.0-py2.7-macosx-10.9-intel.egg/pandas/core/frame.py", line 434, in __init__
    copy=copy)
  File "/Library/Python/2.7/site-packages/pandas-0.12.0-py2.7-macosx-10.9-intel.egg/pandas/core/frame.py", line 561, in _init_ndarray
    return create_block_manager_from_blocks([ values.T ], [ columns, index ])
  File "/Library/Python/2.7/site-packages/pandas-0.12.0-py2.7-macosx-10.9-intel.egg/pandas/core/internals.py", line 2234, in create_block_manager_from_blocks
    construction_error(tot_items,blocks[0].shape[1:],axes)
  File "/Library/Python/2.7/site-packages/pandas-0.12.0-py2.7-macosx-10.9-intel.egg/pandas/core/internals.py", line 2216, in construction_error
    tuple(map(int, [len(ax) for ax in axes]))))
ValueError: Shape of passed values is (0, 0), indices imply (8, 0)

--------------------------------------------------------------------------------
2014/01/18 18:03:34 - Error in handler <bound method TradeBot.onNewDepth of <__main__.TradeBot object at 0x10660b450>> for btc_eur depth
Traceback (most recent call last):
  File "/Library/Python/2.7/site-packages/btcebot/bot.py", line 52, in _runBot
    handler(t, p, asks, bids)
  File "/Users/afansky/dev/code/bitcoin_bot/trade-bot/tradebot/tradebot.py", line 29, in onNewDepth
    self.analyzer.analyze(t, pair)
  File "/Users/afansky/dev/code/bitcoin_bot/trade-bot/tradebot/analysis/analysis.py", line 19, in analyze
    df = create_data_frame(ticks)
  File "/Users/afansky/dev/code/bitcoin_bot/trade-bot/tradebot/analysis/analysis.py", line 42, in create_data_frame
    return pd.DataFrame(ticks_new, columns=['high_price', 'low_price', 'avg_price', 'last_price', 'buy_price', 'sell_price', 'volume', 'current_volume'], index=index)
  File "/Library/Python/2.7/site-packages/pandas-0.12.0-py2.7-macosx-10.9-intel.egg/pandas/core/frame.py", line 434, in __init__
    copy=copy)
  File "/Library/Python/2.7/site-packages/pandas-0.12.0-py2.7-macosx-10.9-intel.egg/pandas/core/frame.py", line 561, in _init_ndarray
    return create_block_manager_from_blocks([ values.T ], [ columns, index ])
  File "/Library/Python/2.7/site-packages/pandas-0.12.0-py2.7-macosx-10.9-intel.egg/pandas/core/internals.py", line 2234, in create_block_manager_from_blocks
    construction_error(tot_items,blocks[0].shape[1:],axes)
  File "/Library/Python/2.7/site-packages/pandas-0.12.0-py2.7-macosx-10.9-intel.egg/pandas/core/internals.py", line 2216, in construction_error
    tuple(map(int, [len(ax) for ax in axes]))))
ValueError: Shape of passed values is (0, 0), indices imply (8, 0)

--------------------------------------------------------------------------------
2014/01/18 18:03:34 - Error in handler <bound method TradeBot.onNewDepth of <__main__.TradeBot object at 0x10660b450>> for btc_rur depth
Traceback (most recent call last):
  File "/Library/Python/2.7/site-packages/btcebot/bot.py", line 52, in _runBot
    handler(t, p, asks, bids)
  File "/Users/afansky/dev/code/bitcoin_bot/trade-bot/tradebot/tradebot.py", line 29, in onNewDepth
    self.analyzer.analyze(t, pair)
  File "/Users/afansky/dev/code/bitcoin_bot/trade-bot/tradebot/analysis/analysis.py", line 19, in analyze
    df = create_data_frame(ticks)
  File "/Users/afansky/dev/code/bitcoin_bot/trade-bot/tradebot/analysis/analysis.py", line 42, in create_data_frame
    return pd.DataFrame(ticks_new, columns=['high_price', 'low_price', 'avg_price', 'last_price', 'buy_price', 'sell_price', 'volume', 'current_volume'], index=index)
  File "/Library/Python/2.7/site-packages/pandas-0.12.0-py2.7-macosx-10.9-intel.egg/pandas/core/frame.py", line 434, in __init__
    copy=copy)
  File "/Library/Python/2.7/site-packages/pandas-0.12.0-py2.7-macosx-10.9-intel.egg/pandas/core/frame.py", line 561, in _init_ndarray
    return create_block_manager_from_blocks([ values.T ], [ columns, index ])
  File "/Library/Python/2.7/site-packages/pandas-0.12.0-py2.7-macosx-10.9-intel.egg/pandas/core/internals.py", line 2234, in create_block_manager_from_blocks
    construction_error(tot_items,blocks[0].shape[1:],axes)
  File "/Library/Python/2.7/site-packages/pandas-0.12.0-py2.7-macosx-10.9-intel.egg/pandas/core/internals.py", line 2216, in construction_error
    tuple(map(int, [len(ax) for ax in axes]))))
ValueError: Shape of passed values is (0, 0), indices imply (8, 0)

--------------------------------------------------------------------------------
2014/01/18 18:05:09 - Error in handler <bound method TradeBot.onNewDepth of <__main__.TradeBot object at 0x10b409450>> for ltc_eur depth
Traceback (most recent call last):
  File "/Library/Python/2.7/site-packages/btcebot/bot.py", line 52, in _runBot
    handler(t, p, asks, bids)
  File "/Users/afansky/dev/code/bitcoin_bot/trade-bot/tradebot/tradebot.py", line 29, in onNewDepth
    self.analyzer.analyze(t, pair)
  File "/Users/afansky/dev/code/bitcoin_bot/trade-bot/tradebot/analysis/analysis.py", line 19, in analyze
    df = create_data_frame(ticks)
  File "/Users/afansky/dev/code/bitcoin_bot/trade-bot/tradebot/analysis/analysis.py", line 42, in create_data_frame
    return pd.DataFrame(ticks_new, columns=['high_price', 'low_price', 'avg_price', 'last_price', 'buy_price', 'sell_price', 'volume', 'current_volume'], index=index)
  File "/Library/Python/2.7/site-packages/pandas-0.12.0-py2.7-macosx-10.9-intel.egg/pandas/core/frame.py", line 434, in __init__
    copy=copy)
  File "/Library/Python/2.7/site-packages/pandas-0.12.0-py2.7-macosx-10.9-intel.egg/pandas/core/frame.py", line 561, in _init_ndarray
    return create_block_manager_from_blocks([ values.T ], [ columns, index ])
  File "/Library/Python/2.7/site-packages/pandas-0.12.0-py2.7-macosx-10.9-intel.egg/pandas/core/internals.py", line 2234, in create_block_manager_from_blocks
    construction_error(tot_items,blocks[0].shape[1:],axes)
  File "/Library/Python/2.7/site-packages/pandas-0.12.0-py2.7-macosx-10.9-intel.egg/pandas/core/internals.py", line 2216, in construction_error
    tuple(map(int, [len(ax) for ax in axes]))))
ValueError: Shape of passed values is (0, 0), indices imply (8, 0)

--------------------------------------------------------------------------------
2014/01/18 18:05:09 - Error in handler <bound method TradeBot.onNewDepth of <__main__.TradeBot object at 0x10b409450>> for btc_usd depth
Traceback (most recent call last):
  File "/Library/Python/2.7/site-packages/btcebot/bot.py", line 52, in _runBot
    handler(t, p, asks, bids)
  File "/Users/afansky/dev/code/bitcoin_bot/trade-bot/tradebot/tradebot.py", line 29, in onNewDepth
    self.analyzer.analyze(t, pair)
  File "/Users/afansky/dev/code/bitcoin_bot/trade-bot/tradebot/analysis/analysis.py", line 19, in analyze
    df = create_data_frame(ticks)
  File "/Users/afansky/dev/code/bitcoin_bot/trade-bot/tradebot/analysis/analysis.py", line 42, in create_data_frame
    return pd.DataFrame(ticks_new, columns=['high_price', 'low_price', 'avg_price', 'last_price', 'buy_price', 'sell_price', 'volume', 'current_volume'], index=index)
  File "/Library/Python/2.7/site-packages/pandas-0.12.0-py2.7-macosx-10.9-intel.egg/pandas/core/frame.py", line 434, in __init__
    copy=copy)
  File "/Library/Python/2.7/site-packages/pandas-0.12.0-py2.7-macosx-10.9-intel.egg/pandas/core/frame.py", line 561, in _init_ndarray
    return create_block_manager_from_blocks([ values.T ], [ columns, index ])
  File "/Library/Python/2.7/site-packages/pandas-0.12.0-py2.7-macosx-10.9-intel.egg/pandas/core/internals.py", line 2234, in create_block_manager_from_blocks
    construction_error(tot_items,blocks[0].shape[1:],axes)
  File "/Library/Python/2.7/site-packages/pandas-0.12.0-py2.7-macosx-10.9-intel.egg/pandas/core/internals.py", line 2216, in construction_error
    tuple(map(int, [len(ax) for ax in axes]))))
ValueError: Shape of passed values is (0, 0), indices imply (8, 0)

--------------------------------------------------------------------------------
2014/01/18 18:05:09 - Error in handler <bound method TradeBot.onNewDepth of <__main__.TradeBot object at 0x10b409450>> for ltc_btc depth
Traceback (most recent call last):
  File "/Library/Python/2.7/site-packages/btcebot/bot.py", line 52, in _runBot
    handler(t, p, asks, bids)
  File "/Users/afansky/dev/code/bitcoin_bot/trade-bot/tradebot/tradebot.py", line 29, in onNewDepth
    self.analyzer.analyze(t, pair)
  File "/Users/afansky/dev/code/bitcoin_bot/trade-bot/tradebot/analysis/analysis.py", line 19, in analyze
    df = create_data_frame(ticks)
  File "/Users/afansky/dev/code/bitcoin_bot/trade-bot/tradebot/analysis/analysis.py", line 42, in create_data_frame
    return pd.DataFrame(ticks_new, columns=['high_price', 'low_price', 'avg_price', 'last_price', 'buy_price', 'sell_price', 'volume', 'current_volume'], index=index)
  File "/Library/Python/2.7/site-packages/pandas-0.12.0-py2.7-macosx-10.9-intel.egg/pandas/core/frame.py", line 434, in __init__
    copy=copy)
  File "/Library/Python/2.7/site-packages/pandas-0.12.0-py2.7-macosx-10.9-intel.egg/pandas/core/frame.py", line 561, in _init_ndarray
    return create_block_manager_from_blocks([ values.T ], [ columns, index ])
  File "/Library/Python/2.7/site-packages/pandas-0.12.0-py2.7-macosx-10.9-intel.egg/pandas/core/internals.py", line 2234, in create_block_manager_from_blocks
    construction_error(tot_items,blocks[0].shape[1:],axes)
  File "/Library/Python/2.7/site-packages/pandas-0.12.0-py2.7-macosx-10.9-intel.egg/pandas/core/internals.py", line 2216, in construction_error
    tuple(map(int, [len(ax) for ax in axes]))))
ValueError: Shape of passed values is (0, 0), indices imply (8, 0)

--------------------------------------------------------------------------------
2014/01/18 18:05:09 - Error in handler <bound method TradeBot.onNewDepth of <__main__.TradeBot object at 0x10b409450>> for ltc_rur depth
Traceback (most recent call last):
  File "/Library/Python/2.7/site-packages/btcebot/bot.py", line 52, in _runBot
    handler(t, p, asks, bids)
  File "/Users/afansky/dev/code/bitcoin_bot/trade-bot/tradebot/tradebot.py", line 29, in onNewDepth
    self.analyzer.analyze(t, pair)
  File "/Users/afansky/dev/code/bitcoin_bot/trade-bot/tradebot/analysis/analysis.py", line 19, in analyze
    df = create_data_frame(ticks)
  File "/Users/afansky/dev/code/bitcoin_bot/trade-bot/tradebot/analysis/analysis.py", line 42, in create_data_frame
    return pd.DataFrame(ticks_new, columns=['high_price', 'low_price', 'avg_price', 'last_price', 'buy_price', 'sell_price', 'volume', 'current_volume'], index=index)
  File "/Library/Python/2.7/site-packages/pandas-0.12.0-py2.7-macosx-10.9-intel.egg/pandas/core/frame.py", line 434, in __init__
    copy=copy)
  File "/Library/Python/2.7/site-packages/pandas-0.12.0-py2.7-macosx-10.9-intel.egg/pandas/core/frame.py", line 561, in _init_ndarray
    return create_block_manager_from_blocks([ values.T ], [ columns, index ])
  File "/Library/Python/2.7/site-packages/pandas-0.12.0-py2.7-macosx-10.9-intel.egg/pandas/core/internals.py", line 2234, in create_block_manager_from_blocks
    construction_error(tot_items,blocks[0].shape[1:],axes)
  File "/Library/Python/2.7/site-packages/pandas-0.12.0-py2.7-macosx-10.9-intel.egg/pandas/core/internals.py", line 2216, in construction_error
    tuple(map(int, [len(ax) for ax in axes]))))
ValueError: Shape of passed values is (0, 0), indices imply (8, 0)

--------------------------------------------------------------------------------
2014/01/18 18:05:09 - Error in handler <bound method TradeBot.onNewDepth of <__main__.TradeBot object at 0x10b409450>> for ltc_usd depth
Traceback (most recent call last):
  File "/Library/Python/2.7/site-packages/btcebot/bot.py", line 52, in _runBot
    handler(t, p, asks, bids)
  File "/Users/afansky/dev/code/bitcoin_bot/trade-bot/tradebot/tradebot.py", line 29, in onNewDepth
    self.analyzer.analyze(t, pair)
  File "/Users/afansky/dev/code/bitcoin_bot/trade-bot/tradebot/analysis/analysis.py", line 19, in analyze
    df = create_data_frame(ticks)
  File "/Users/afansky/dev/code/bitcoin_bot/trade-bot/tradebot/analysis/analysis.py", line 42, in create_data_frame
    return pd.DataFrame(ticks_new, columns=['high_price', 'low_price', 'avg_price', 'last_price', 'buy_price', 'sell_price', 'volume', 'current_volume'], index=index)
  File "/Library/Python/2.7/site-packages/pandas-0.12.0-py2.7-macosx-10.9-intel.egg/pandas/core/frame.py", line 434, in __init__
    copy=copy)
  File "/Library/Python/2.7/site-packages/pandas-0.12.0-py2.7-macosx-10.9-intel.egg/pandas/core/frame.py", line 561, in _init_ndarray
    return create_block_manager_from_blocks([ values.T ], [ columns, index ])
  File "/Library/Python/2.7/site-packages/pandas-0.12.0-py2.7-macosx-10.9-intel.egg/pandas/core/internals.py", line 2234, in create_block_manager_from_blocks
    construction_error(tot_items,blocks[0].shape[1:],axes)
  File "/Library/Python/2.7/site-packages/pandas-0.12.0-py2.7-macosx-10.9-intel.egg/pandas/core/internals.py", line 2216, in construction_error
    tuple(map(int, [len(ax) for ax in axes]))))
ValueError: Shape of passed values is (0, 0), indices imply (8, 0)

--------------------------------------------------------------------------------
2014/01/18 18:05:09 - Error in handler <bound method TradeBot.onNewDepth of <__main__.TradeBot object at 0x10b409450>> for btc_eur depth
Traceback (most recent call last):
  File "/Library/Python/2.7/site-packages/btcebot/bot.py", line 52, in _runBot
    handler(t, p, asks, bids)
  File "/Users/afansky/dev/code/bitcoin_bot/trade-bot/tradebot/tradebot.py", line 29, in onNewDepth
    self.analyzer.analyze(t, pair)
  File "/Users/afansky/dev/code/bitcoin_bot/trade-bot/tradebot/analysis/analysis.py", line 19, in analyze
    df = create_data_frame(ticks)
  File "/Users/afansky/dev/code/bitcoin_bot/trade-bot/tradebot/analysis/analysis.py", line 42, in create_data_frame
    return pd.DataFrame(ticks_new, columns=['high_price', 'low_price', 'avg_price', 'last_price', 'buy_price', 'sell_price', 'volume', 'current_volume'], index=index)
  File "/Library/Python/2.7/site-packages/pandas-0.12.0-py2.7-macosx-10.9-intel.egg/pandas/core/frame.py", line 434, in __init__
    copy=copy)
  File "/Library/Python/2.7/site-packages/pandas-0.12.0-py2.7-macosx-10.9-intel.egg/pandas/core/frame.py", line 561, in _init_ndarray
    return create_block_manager_from_blocks([ values.T ], [ columns, index ])
  File "/Library/Python/2.7/site-packages/pandas-0.12.0-py2.7-macosx-10.9-intel.egg/pandas/core/internals.py", line 2234, in create_block_manager_from_blocks
    construction_error(tot_items,blocks[0].shape[1:],axes)
  File "/Library/Python/2.7/site-packages/pandas-0.12.0-py2.7-macosx-10.9-intel.egg/pandas/core/internals.py", line 2216, in construction_error
    tuple(map(int, [len(ax) for ax in axes]))))
ValueError: Shape of passed values is (0, 0), indices imply (8, 0)

--------------------------------------------------------------------------------
2014/01/18 18:05:09 - Error in handler <bound method TradeBot.onNewDepth of <__main__.TradeBot object at 0x10b409450>> for btc_rur depth
Traceback (most recent call last):
  File "/Library/Python/2.7/site-packages/btcebot/bot.py", line 52, in _runBot
    handler(t, p, asks, bids)
  File "/Users/afansky/dev/code/bitcoin_bot/trade-bot/tradebot/tradebot.py", line 29, in onNewDepth
    self.analyzer.analyze(t, pair)
  File "/Users/afansky/dev/code/bitcoin_bot/trade-bot/tradebot/analysis/analysis.py", line 19, in analyze
    df = create_data_frame(ticks)
  File "/Users/afansky/dev/code/bitcoin_bot/trade-bot/tradebot/analysis/analysis.py", line 42, in create_data_frame
    return pd.DataFrame(ticks_new, columns=['high_price', 'low_price', 'avg_price', 'last_price', 'buy_price', 'sell_price', 'volume', 'current_volume'], index=index)
  File "/Library/Python/2.7/site-packages/pandas-0.12.0-py2.7-macosx-10.9-intel.egg/pandas/core/frame.py", line 434, in __init__
    copy=copy)
  File "/Library/Python/2.7/site-packages/pandas-0.12.0-py2.7-macosx-10.9-intel.egg/pandas/core/frame.py", line 561, in _init_ndarray
    return create_block_manager_from_blocks([ values.T ], [ columns, index ])
  File "/Library/Python/2.7/site-packages/pandas-0.12.0-py2.7-macosx-10.9-intel.egg/pandas/core/internals.py", line 2234, in create_block_manager_from_blocks
    construction_error(tot_items,blocks[0].shape[1:],axes)
  File "/Library/Python/2.7/site-packages/pandas-0.12.0-py2.7-macosx-10.9-intel.egg/pandas/core/internals.py", line 2216, in construction_error
    tuple(map(int, [len(ax) for ax in axes]))))
ValueError: Shape of passed values is (0, 0), indices imply (8, 0)

--------------------------------------------------------------------------------
2014/01/18 19:53:53 - Error in handler <bound method TradeBot.onNewDepth of <__main__.TradeBot object at 0x10ed74350>> for ltc_eur depth
Traceback (most recent call last):
  File "/Library/Python/2.7/site-packages/btcebot/bot.py", line 52, in _runBot
    handler(t, p, asks, bids)
  File "/Users/afansky/dev/code/bitcoin_bot/trade-bot/tradebot/tradebot.py", line 23, in onNewDepth
    self.analyzer.analyze(t, pair)
  File "/Users/afansky/dev/code/bitcoin_bot/trade-bot/tradebot/analysis/analysis.py", line 20, in analyze
    if len(ticks) == 0:
TypeError: object of type 'Cursor' has no len()

--------------------------------------------------------------------------------
2014/01/18 19:53:53 - Error in handler <bound method TradeBot.onNewDepth of <__main__.TradeBot object at 0x10ed74350>> for btc_usd depth
Traceback (most recent call last):
  File "/Library/Python/2.7/site-packages/btcebot/bot.py", line 52, in _runBot
    handler(t, p, asks, bids)
  File "/Users/afansky/dev/code/bitcoin_bot/trade-bot/tradebot/tradebot.py", line 23, in onNewDepth
    self.analyzer.analyze(t, pair)
  File "/Users/afansky/dev/code/bitcoin_bot/trade-bot/tradebot/analysis/analysis.py", line 20, in analyze
    if len(ticks) == 0:
TypeError: object of type 'Cursor' has no len()

--------------------------------------------------------------------------------
2014/01/18 19:53:53 - Error in handler <bound method TradeBot.onNewDepth of <__main__.TradeBot object at 0x10ed74350>> for ltc_btc depth
Traceback (most recent call last):
  File "/Library/Python/2.7/site-packages/btcebot/bot.py", line 52, in _runBot
    handler(t, p, asks, bids)
  File "/Users/afansky/dev/code/bitcoin_bot/trade-bot/tradebot/tradebot.py", line 23, in onNewDepth
    self.analyzer.analyze(t, pair)
  File "/Users/afansky/dev/code/bitcoin_bot/trade-bot/tradebot/analysis/analysis.py", line 20, in analyze
    if len(ticks) == 0:
TypeError: object of type 'Cursor' has no len()

--------------------------------------------------------------------------------
2014/01/18 19:53:53 - Error in handler <bound method TradeBot.onNewDepth of <__main__.TradeBot object at 0x10ed74350>> for ltc_rur depth
Traceback (most recent call last):
  File "/Library/Python/2.7/site-packages/btcebot/bot.py", line 52, in _runBot
    handler(t, p, asks, bids)
  File "/Users/afansky/dev/code/bitcoin_bot/trade-bot/tradebot/tradebot.py", line 23, in onNewDepth
    self.analyzer.analyze(t, pair)
  File "/Users/afansky/dev/code/bitcoin_bot/trade-bot/tradebot/analysis/analysis.py", line 20, in analyze
    if len(ticks) == 0:
TypeError: object of type 'Cursor' has no len()

--------------------------------------------------------------------------------
2014/01/18 19:53:53 - Error in handler <bound method TradeBot.onNewDepth of <__main__.TradeBot object at 0x10ed74350>> for ltc_usd depth
Traceback (most recent call last):
  File "/Library/Python/2.7/site-packages/btcebot/bot.py", line 52, in _runBot
    handler(t, p, asks, bids)
  File "/Users/afansky/dev/code/bitcoin_bot/trade-bot/tradebot/tradebot.py", line 23, in onNewDepth
    self.analyzer.analyze(t, pair)
  File "/Users/afansky/dev/code/bitcoin_bot/trade-bot/tradebot/analysis/analysis.py", line 20, in analyze
    if len(ticks) == 0:
TypeError: object of type 'Cursor' has no len()

--------------------------------------------------------------------------------
2014/01/18 19:53:53 - Error in handler <bound method TradeBot.onNewDepth of <__main__.TradeBot object at 0x10ed74350>> for btc_eur depth
Traceback (most recent call last):
  File "/Library/Python/2.7/site-packages/btcebot/bot.py", line 52, in _runBot
    handler(t, p, asks, bids)
  File "/Users/afansky/dev/code/bitcoin_bot/trade-bot/tradebot/tradebot.py", line 23, in onNewDepth
    self.analyzer.analyze(t, pair)
  File "/Users/afansky/dev/code/bitcoin_bot/trade-bot/tradebot/analysis/analysis.py", line 20, in analyze
    if len(ticks) == 0:
TypeError: object of type 'Cursor' has no len()

--------------------------------------------------------------------------------
2014/01/18 19:53:53 - Error in handler <bound method TradeBot.onNewDepth of <__main__.TradeBot object at 0x10ed74350>> for btc_rur depth
Traceback (most recent call last):
  File "/Library/Python/2.7/site-packages/btcebot/bot.py", line 52, in _runBot
    handler(t, p, asks, bids)
  File "/Users/afansky/dev/code/bitcoin_bot/trade-bot/tradebot/tradebot.py", line 23, in onNewDepth
    self.analyzer.analyze(t, pair)
  File "/Users/afansky/dev/code/bitcoin_bot/trade-bot/tradebot/analysis/analysis.py", line 20, in analyze
    if len(ticks) == 0:
TypeError: object of type 'Cursor' has no len()

--------------------------------------------------------------------------------
2014/01/18 19:56:37 - Error while retrieving ltc_rur ticker
Traceback (most recent call last):
  File "/Library/Python/2.7/site-packages/btcebot/bot.py", line 100, in _ticker_loop
    response = btceapi.getTicker(p, conn)
  File "/Library/Python/2.7/site-packages/btceapi/public.py", line 50, in getTicker
    response = connection.makeJSONRequest("/api/2/%s/ticker" % pair)
  File "/Library/Python/2.7/site-packages/btceapi/common.py", line 118, in makeJSONRequest
    response = self.makeRequest(url, extra_headers, params)
  File "/Library/Python/2.7/site-packages/btceapi/common.py", line 113, in makeRequest
    response = self.conn.getresponse().read()
  File "/System/Library/Frameworks/Python.framework/Versions/2.7/lib/python2.7/httplib.py", line 1045, in getresponse
    response.begin()
  File "/System/Library/Frameworks/Python.framework/Versions/2.7/lib/python2.7/httplib.py", line 409, in begin
    version, status, reason = self._read_status()
  File "/System/Library/Frameworks/Python.framework/Versions/2.7/lib/python2.7/httplib.py", line 373, in _read_status
    raise BadStatusLine(line)
BadStatusLine: ''

--------------------------------------------------------------------------------
2014/01/18 19:56:37 - Error while retrieving ltc_usd ticker
Traceback (most recent call last):
  File "/Library/Python/2.7/site-packages/btcebot/bot.py", line 100, in _ticker_loop
    response = btceapi.getTicker(p, conn)
  File "/Library/Python/2.7/site-packages/btceapi/public.py", line 50, in getTicker
    response = connection.makeJSONRequest("/api/2/%s/ticker" % pair)
  File "/Library/Python/2.7/site-packages/btceapi/common.py", line 118, in makeJSONRequest
    response = self.makeRequest(url, extra_headers, params)
  File "/Library/Python/2.7/site-packages/btceapi/common.py", line 112, in makeRequest
    self.conn.request("POST", url, params, headers)
  File "/System/Library/Frameworks/Python.framework/Versions/2.7/lib/python2.7/httplib.py", line 973, in request
    self._send_request(method, url, body, headers)
  File "/System/Library/Frameworks/Python.framework/Versions/2.7/lib/python2.7/httplib.py", line 1001, in _send_request
    self.putrequest(method, url, **skips)
  File "/System/Library/Frameworks/Python.framework/Versions/2.7/lib/python2.7/httplib.py", line 871, in putrequest
    raise CannotSendRequest()
CannotSendRequest

--------------------------------------------------------------------------------
2014/01/18 19:56:37 - Error while retrieving btc_eur ticker
Traceback (most recent call last):
  File "/Library/Python/2.7/site-packages/btcebot/bot.py", line 100, in _ticker_loop
    response = btceapi.getTicker(p, conn)
  File "/Library/Python/2.7/site-packages/btceapi/public.py", line 50, in getTicker
    response = connection.makeJSONRequest("/api/2/%s/ticker" % pair)
  File "/Library/Python/2.7/site-packages/btceapi/common.py", line 118, in makeJSONRequest
    response = self.makeRequest(url, extra_headers, params)
  File "/Library/Python/2.7/site-packages/btceapi/common.py", line 112, in makeRequest
    self.conn.request("POST", url, params, headers)
  File "/System/Library/Frameworks/Python.framework/Versions/2.7/lib/python2.7/httplib.py", line 973, in request
    self._send_request(method, url, body, headers)
  File "/System/Library/Frameworks/Python.framework/Versions/2.7/lib/python2.7/httplib.py", line 1001, in _send_request
    self.putrequest(method, url, **skips)
  File "/System/Library/Frameworks/Python.framework/Versions/2.7/lib/python2.7/httplib.py", line 871, in putrequest
    raise CannotSendRequest()
CannotSendRequest

--------------------------------------------------------------------------------
2014/01/18 19:56:37 - Error while retrieving btc_rur ticker
Traceback (most recent call last):
  File "/Library/Python/2.7/site-packages/btcebot/bot.py", line 100, in _ticker_loop
    response = btceapi.getTicker(p, conn)
  File "/Library/Python/2.7/site-packages/btceapi/public.py", line 50, in getTicker
    response = connection.makeJSONRequest("/api/2/%s/ticker" % pair)
  File "/Library/Python/2.7/site-packages/btceapi/common.py", line 118, in makeJSONRequest
    response = self.makeRequest(url, extra_headers, params)
  File "/Library/Python/2.7/site-packages/btceapi/common.py", line 112, in makeRequest
    self.conn.request("POST", url, params, headers)
  File "/System/Library/Frameworks/Python.framework/Versions/2.7/lib/python2.7/httplib.py", line 973, in request
    self._send_request(method, url, body, headers)
  File "/System/Library/Frameworks/Python.framework/Versions/2.7/lib/python2.7/httplib.py", line 1001, in _send_request
    self.putrequest(method, url, **skips)
  File "/System/Library/Frameworks/Python.framework/Versions/2.7/lib/python2.7/httplib.py", line 871, in putrequest
    raise CannotSendRequest()
CannotSendRequest

--------------------------------------------------------------------------------
2014/01/18 19:56:57 - Error in handler <bound method TradeBot.onNewDepth of <__main__.TradeBot object at 0x108d97350>> for ltc_eur depth
Traceback (most recent call last):
  File "/Library/Python/2.7/site-packages/btcebot/bot.py", line 52, in _runBot
    handler(t, p, asks, bids)
  File "/Users/afansky/dev/code/bitcoin_bot/trade-bot/tradebot/tradebot.py", line 23, in onNewDepth
    self.analyzer.analyze(t, pair)
  File "/Users/afansky/dev/code/bitcoin_bot/trade-bot/tradebot/analysis/analysis.py", line 20, in analyze
    if len(ticks) == 0:
TypeError: object of type 'Cursor' has no len()

--------------------------------------------------------------------------------
2014/01/18 20:09:27 - Error in handler <bound method TradeBot.onNewDepth of <__main__.TradeBot object at 0x107b26350>> for ltc_eur depth
Traceback (most recent call last):
  File "/Library/Python/2.7/site-packages/btcebot/bot.py", line 52, in _runBot
    handler(t, p, asks, bids)
  File "/Users/afansky/dev/code/bitcoin_bot/trade-bot/tradebot/tradebot.py", line 23, in onNewDepth
    self.analyzer.analyze(t, pair)
  File "/Users/afansky/dev/code/bitcoin_bot/trade-bot/tradebot/analysis/analysis.py", line 20, in analyze
    if len(ticks) == 0:
TypeError: object of type 'Cursor' has no len()

--------------------------------------------------------------------------------
2014/01/18 20:12:38 - Error in handler <bound method TradeBot.onNewDepth of <__main__.TradeBot object at 0x110bc6350>> for ltc_eur depth
Traceback (most recent call last):
  File "/Library/Python/2.7/site-packages/btcebot/bot.py", line 52, in _runBot
    handler(t, p, asks, bids)
  File "/Users/afansky/dev/code/bitcoin_bot/trade-bot/tradebot/tradebot.py", line 23, in onNewDepth
    self.analyzer.analyze(t, pair)
  File "/Users/afansky/dev/code/bitcoin_bot/trade-bot/tradebot/analysis/analysis.py", line 20, in analyze
    if len(ticks) == 0:
TypeError: object of type 'Cursor' has no len()

--------------------------------------------------------------------------------
2014/01/18 20:12:38 - Error in handler <bound method TradeBot.onNewDepth of <__main__.TradeBot object at 0x110bc6350>> for btc_usd depth
Traceback (most recent call last):
  File "/Library/Python/2.7/site-packages/btcebot/bot.py", line 52, in _runBot
    handler(t, p, asks, bids)
  File "/Users/afansky/dev/code/bitcoin_bot/trade-bot/tradebot/tradebot.py", line 23, in onNewDepth
    self.analyzer.analyze(t, pair)
  File "/Users/afansky/dev/code/bitcoin_bot/trade-bot/tradebot/analysis/analysis.py", line 20, in analyze
    if len(ticks) == 0:
TypeError: object of type 'Cursor' has no len()

--------------------------------------------------------------------------------
2014/01/18 20:12:38 - Error in handler <bound method TradeBot.onNewDepth of <__main__.TradeBot object at 0x110bc6350>> for ltc_btc depth
Traceback (most recent call last):
  File "/Library/Python/2.7/site-packages/btcebot/bot.py", line 52, in _runBot
    handler(t, p, asks, bids)
  File "/Users/afansky/dev/code/bitcoin_bot/trade-bot/tradebot/tradebot.py", line 23, in onNewDepth
    self.analyzer.analyze(t, pair)
  File "/Users/afansky/dev/code/bitcoin_bot/trade-bot/tradebot/analysis/analysis.py", line 20, in analyze
    if len(ticks) == 0:
TypeError: object of type 'Cursor' has no len()

--------------------------------------------------------------------------------
2014/01/18 20:12:38 - Error in handler <bound method TradeBot.onNewDepth of <__main__.TradeBot object at 0x110bc6350>> for ltc_rur depth
Traceback (most recent call last):
  File "/Library/Python/2.7/site-packages/btcebot/bot.py", line 52, in _runBot
    handler(t, p, asks, bids)
  File "/Users/afansky/dev/code/bitcoin_bot/trade-bot/tradebot/tradebot.py", line 23, in onNewDepth
    self.analyzer.analyze(t, pair)
  File "/Users/afansky/dev/code/bitcoin_bot/trade-bot/tradebot/analysis/analysis.py", line 20, in analyze
    if len(ticks) == 0:
TypeError: object of type 'Cursor' has no len()

--------------------------------------------------------------------------------
2014/01/18 20:12:38 - Error in handler <bound method TradeBot.onNewDepth of <__main__.TradeBot object at 0x110bc6350>> for ltc_usd depth
Traceback (most recent call last):
  File "/Library/Python/2.7/site-packages/btcebot/bot.py", line 52, in _runBot
    handler(t, p, asks, bids)
  File "/Users/afansky/dev/code/bitcoin_bot/trade-bot/tradebot/tradebot.py", line 23, in onNewDepth
    self.analyzer.analyze(t, pair)
  File "/Users/afansky/dev/code/bitcoin_bot/trade-bot/tradebot/analysis/analysis.py", line 20, in analyze
    if len(ticks) == 0:
TypeError: object of type 'Cursor' has no len()

--------------------------------------------------------------------------------
2014/01/18 20:12:38 - Error in handler <bound method TradeBot.onNewDepth of <__main__.TradeBot object at 0x110bc6350>> for btc_eur depth
Traceback (most recent call last):
  File "/Library/Python/2.7/site-packages/btcebot/bot.py", line 52, in _runBot
    handler(t, p, asks, bids)
  File "/Users/afansky/dev/code/bitcoin_bot/trade-bot/tradebot/tradebot.py", line 23, in onNewDepth
    self.analyzer.analyze(t, pair)
  File "/Users/afansky/dev/code/bitcoin_bot/trade-bot/tradebot/analysis/analysis.py", line 20, in analyze
    if len(ticks) == 0:
TypeError: object of type 'Cursor' has no len()

--------------------------------------------------------------------------------
2014/01/18 20:12:38 - Error in handler <bound method TradeBot.onNewDepth of <__main__.TradeBot object at 0x110bc6350>> for btc_rur depth
Traceback (most recent call last):
  File "/Library/Python/2.7/site-packages/btcebot/bot.py", line 52, in _runBot
    handler(t, p, asks, bids)
  File "/Users/afansky/dev/code/bitcoin_bot/trade-bot/tradebot/tradebot.py", line 23, in onNewDepth
    self.analyzer.analyze(t, pair)
  File "/Users/afansky/dev/code/bitcoin_bot/trade-bot/tradebot/analysis/analysis.py", line 20, in analyze
    if len(ticks) == 0:
TypeError: object of type 'Cursor' has no len()

--------------------------------------------------------------------------------
2014/01/18 20:12:42 - Error while retrieving btc_usd ticker
Traceback (most recent call last):
  File "/Library/Python/2.7/site-packages/btcebot/bot.py", line 100, in _ticker_loop
    response = btceapi.getTicker(p, conn)
  File "/Library/Python/2.7/site-packages/btceapi/public.py", line 50, in getTicker
    response = connection.makeJSONRequest("/api/2/%s/ticker" % pair)
  File "/Library/Python/2.7/site-packages/btceapi/common.py", line 118, in makeJSONRequest
    response = self.makeRequest(url, extra_headers, params)
  File "/Library/Python/2.7/site-packages/btceapi/common.py", line 113, in makeRequest
    response = self.conn.getresponse().read()
  File "/System/Library/Frameworks/Python.framework/Versions/2.7/lib/python2.7/httplib.py", line 1045, in getresponse
    response.begin()
  File "/System/Library/Frameworks/Python.framework/Versions/2.7/lib/python2.7/httplib.py", line 409, in begin
    version, status, reason = self._read_status()
  File "/System/Library/Frameworks/Python.framework/Versions/2.7/lib/python2.7/httplib.py", line 373, in _read_status
    raise BadStatusLine(line)
BadStatusLine: ''

--------------------------------------------------------------------------------
2014/01/18 20:12:42 - Error while retrieving ltc_btc ticker
Traceback (most recent call last):
  File "/Library/Python/2.7/site-packages/btcebot/bot.py", line 100, in _ticker_loop
    response = btceapi.getTicker(p, conn)
  File "/Library/Python/2.7/site-packages/btceapi/public.py", line 50, in getTicker
    response = connection.makeJSONRequest("/api/2/%s/ticker" % pair)
  File "/Library/Python/2.7/site-packages/btceapi/common.py", line 118, in makeJSONRequest
    response = self.makeRequest(url, extra_headers, params)
  File "/Library/Python/2.7/site-packages/btceapi/common.py", line 112, in makeRequest
    self.conn.request("POST", url, params, headers)
  File "/System/Library/Frameworks/Python.framework/Versions/2.7/lib/python2.7/httplib.py", line 973, in request
    self._send_request(method, url, body, headers)
  File "/System/Library/Frameworks/Python.framework/Versions/2.7/lib/python2.7/httplib.py", line 1001, in _send_request
    self.putrequest(method, url, **skips)
  File "/System/Library/Frameworks/Python.framework/Versions/2.7/lib/python2.7/httplib.py", line 871, in putrequest
    raise CannotSendRequest()
CannotSendRequest

--------------------------------------------------------------------------------
2014/01/18 20:12:42 - Error while retrieving ltc_rur ticker
Traceback (most recent call last):
  File "/Library/Python/2.7/site-packages/btcebot/bot.py", line 100, in _ticker_loop
    response = btceapi.getTicker(p, conn)
  File "/Library/Python/2.7/site-packages/btceapi/public.py", line 50, in getTicker
    response = connection.makeJSONRequest("/api/2/%s/ticker" % pair)
  File "/Library/Python/2.7/site-packages/btceapi/common.py", line 118, in makeJSONRequest
    response = self.makeRequest(url, extra_headers, params)
  File "/Library/Python/2.7/site-packages/btceapi/common.py", line 112, in makeRequest
    self.conn.request("POST", url, params, headers)
  File "/System/Library/Frameworks/Python.framework/Versions/2.7/lib/python2.7/httplib.py", line 973, in request
    self._send_request(method, url, body, headers)
  File "/System/Library/Frameworks/Python.framework/Versions/2.7/lib/python2.7/httplib.py", line 1001, in _send_request
    self.putrequest(method, url, **skips)
  File "/System/Library/Frameworks/Python.framework/Versions/2.7/lib/python2.7/httplib.py", line 871, in putrequest
    raise CannotSendRequest()
CannotSendRequest

--------------------------------------------------------------------------------
2014/01/18 20:12:42 - Error while retrieving ltc_usd ticker
Traceback (most recent call last):
  File "/Library/Python/2.7/site-packages/btcebot/bot.py", line 100, in _ticker_loop
    response = btceapi.getTicker(p, conn)
  File "/Library/Python/2.7/site-packages/btceapi/public.py", line 50, in getTicker
    response = connection.makeJSONRequest("/api/2/%s/ticker" % pair)
  File "/Library/Python/2.7/site-packages/btceapi/common.py", line 118, in makeJSONRequest
    response = self.makeRequest(url, extra_headers, params)
  File "/Library/Python/2.7/site-packages/btceapi/common.py", line 112, in makeRequest
    self.conn.request("POST", url, params, headers)
  File "/System/Library/Frameworks/Python.framework/Versions/2.7/lib/python2.7/httplib.py", line 973, in request
    self._send_request(method, url, body, headers)
  File "/System/Library/Frameworks/Python.framework/Versions/2.7/lib/python2.7/httplib.py", line 1001, in _send_request
    self.putrequest(method, url, **skips)
  File "/System/Library/Frameworks/Python.framework/Versions/2.7/lib/python2.7/httplib.py", line 871, in putrequest
    raise CannotSendRequest()
CannotSendRequest

--------------------------------------------------------------------------------
2014/01/18 20:12:42 - Error while retrieving btc_eur ticker
Traceback (most recent call last):
  File "/Library/Python/2.7/site-packages/btcebot/bot.py", line 100, in _ticker_loop
    response = btceapi.getTicker(p, conn)
  File "/Library/Python/2.7/site-packages/btceapi/public.py", line 50, in getTicker
    response = connection.makeJSONRequest("/api/2/%s/ticker" % pair)
  File "/Library/Python/2.7/site-packages/btceapi/common.py", line 118, in makeJSONRequest
    response = self.makeRequest(url, extra_headers, params)
  File "/Library/Python/2.7/site-packages/btceapi/common.py", line 112, in makeRequest
    self.conn.request("POST", url, params, headers)
  File "/System/Library/Frameworks/Python.framework/Versions/2.7/lib/python2.7/httplib.py", line 973, in request
    self._send_request(method, url, body, headers)
  File "/System/Library/Frameworks/Python.framework/Versions/2.7/lib/python2.7/httplib.py", line 1001, in _send_request
    self.putrequest(method, url, **skips)
  File "/System/Library/Frameworks/Python.framework/Versions/2.7/lib/python2.7/httplib.py", line 871, in putrequest
    raise CannotSendRequest()
CannotSendRequest

--------------------------------------------------------------------------------
2014/01/18 20:12:42 - Error while retrieving btc_rur ticker
Traceback (most recent call last):
  File "/Library/Python/2.7/site-packages/btcebot/bot.py", line 100, in _ticker_loop
    response = btceapi.getTicker(p, conn)
  File "/Library/Python/2.7/site-packages/btceapi/public.py", line 50, in getTicker
    response = connection.makeJSONRequest("/api/2/%s/ticker" % pair)
  File "/Library/Python/2.7/site-packages/btceapi/common.py", line 118, in makeJSONRequest
    response = self.makeRequest(url, extra_headers, params)
  File "/Library/Python/2.7/site-packages/btceapi/common.py", line 112, in makeRequest
    self.conn.request("POST", url, params, headers)
  File "/System/Library/Frameworks/Python.framework/Versions/2.7/lib/python2.7/httplib.py", line 973, in request
    self._send_request(method, url, body, headers)
  File "/System/Library/Frameworks/Python.framework/Versions/2.7/lib/python2.7/httplib.py", line 1001, in _send_request
    self.putrequest(method, url, **skips)
  File "/System/Library/Frameworks/Python.framework/Versions/2.7/lib/python2.7/httplib.py", line 871, in putrequest
    raise CannotSendRequest()
CannotSendRequest

--------------------------------------------------------------------------------
2014/01/18 20:14:29 - Error while retrieving ltc_btc depth
Traceback (most recent call last):
  File "/Library/Python/2.7/site-packages/btcebot/bot.py", line 28, in _runBot
    asks, bids = btceapi.getDepth(p, conn)
  File "/Library/Python/2.7/site-packages/btceapi/public.py", line 67, in getDepth
    depth = connection.makeJSONRequest("/api/2/%s/depth" % pair)
  File "/Library/Python/2.7/site-packages/btceapi/common.py", line 118, in makeJSONRequest
    response = self.makeRequest(url, extra_headers, params)
  File "/Library/Python/2.7/site-packages/btceapi/common.py", line 113, in makeRequest
    response = self.conn.getresponse().read()
  File "/System/Library/Frameworks/Python.framework/Versions/2.7/lib/python2.7/httplib.py", line 1045, in getresponse
    response.begin()
  File "/System/Library/Frameworks/Python.framework/Versions/2.7/lib/python2.7/httplib.py", line 409, in begin
    version, status, reason = self._read_status()
  File "/System/Library/Frameworks/Python.framework/Versions/2.7/lib/python2.7/httplib.py", line 373, in _read_status
    raise BadStatusLine(line)
BadStatusLine: ''

--------------------------------------------------------------------------------
2014/01/18 20:14:29 - Error while retrieving btc_usd ticker
Traceback (most recent call last):
  File "/Library/Python/2.7/site-packages/btcebot/bot.py", line 100, in _ticker_loop
    response = btceapi.getTicker(p, conn)
  File "/Library/Python/2.7/site-packages/btceapi/public.py", line 50, in getTicker
    response = connection.makeJSONRequest("/api/2/%s/ticker" % pair)
  File "/Library/Python/2.7/site-packages/btceapi/common.py", line 118, in makeJSONRequest
    response = self.makeRequest(url, extra_headers, params)
  File "/Library/Python/2.7/site-packages/btceapi/common.py", line 113, in makeRequest
    response = self.conn.getresponse().read()
  File "/System/Library/Frameworks/Python.framework/Versions/2.7/lib/python2.7/httplib.py", line 1045, in getresponse
    response.begin()
  File "/System/Library/Frameworks/Python.framework/Versions/2.7/lib/python2.7/httplib.py", line 409, in begin
    version, status, reason = self._read_status()
  File "/System/Library/Frameworks/Python.framework/Versions/2.7/lib/python2.7/httplib.py", line 373, in _read_status
    raise BadStatusLine(line)
BadStatusLine: ''

--------------------------------------------------------------------------------
2014/01/18 20:14:29 - Error while retrieving ltc_rur depth
Traceback (most recent call last):
  File "/Library/Python/2.7/site-packages/btcebot/bot.py", line 28, in _runBot
    asks, bids = btceapi.getDepth(p, conn)
  File "/Library/Python/2.7/site-packages/btceapi/public.py", line 67, in getDepth
    depth = connection.makeJSONRequest("/api/2/%s/depth" % pair)
  File "/Library/Python/2.7/site-packages/btceapi/common.py", line 118, in makeJSONRequest
    response = self.makeRequest(url, extra_headers, params)
  File "/Library/Python/2.7/site-packages/btceapi/common.py", line 112, in makeRequest
    self.conn.request("POST", url, params, headers)
  File "/System/Library/Frameworks/Python.framework/Versions/2.7/lib/python2.7/httplib.py", line 973, in request
    self._send_request(method, url, body, headers)
  File "/System/Library/Frameworks/Python.framework/Versions/2.7/lib/python2.7/httplib.py", line 1001, in _send_request
    self.putrequest(method, url, **skips)
  File "/System/Library/Frameworks/Python.framework/Versions/2.7/lib/python2.7/httplib.py", line 871, in putrequest
    raise CannotSendRequest()
CannotSendRequest

--------------------------------------------------------------------------------
2014/01/18 20:14:29 - Error while retrieving ltc_usd depth
Traceback (most recent call last):
  File "/Library/Python/2.7/site-packages/btcebot/bot.py", line 28, in _runBot
    asks, bids = btceapi.getDepth(p, conn)
  File "/Library/Python/2.7/site-packages/btceapi/public.py", line 67, in getDepth
    depth = connection.makeJSONRequest("/api/2/%s/depth" % pair)
  File "/Library/Python/2.7/site-packages/btceapi/common.py", line 118, in makeJSONRequest
    response = self.makeRequest(url, extra_headers, params)
  File "/Library/Python/2.7/site-packages/btceapi/common.py", line 112, in makeRequest
    self.conn.request("POST", url, params, headers)
  File "/System/Library/Frameworks/Python.framework/Versions/2.7/lib/python2.7/httplib.py", line 973, in request
    self._send_request(method, url, body, headers)
  File "/System/Library/Frameworks/Python.framework/Versions/2.7/lib/python2.7/httplib.py", line 1001, in _send_request
    self.putrequest(method, url, **skips)
  File "/System/Library/Frameworks/Python.framework/Versions/2.7/lib/python2.7/httplib.py", line 871, in putrequest
    raise CannotSendRequest()
CannotSendRequest

--------------------------------------------------------------------------------
2014/01/18 20:14:29 - Error while retrieving ltc_btc ticker
Traceback (most recent call last):
  File "/Library/Python/2.7/site-packages/btcebot/bot.py", line 100, in _ticker_loop
    response = btceapi.getTicker(p, conn)
  File "/Library/Python/2.7/site-packages/btceapi/public.py", line 50, in getTicker
    response = connection.makeJSONRequest("/api/2/%s/ticker" % pair)
  File "/Library/Python/2.7/site-packages/btceapi/common.py", line 118, in makeJSONRequest
    response = self.makeRequest(url, extra_headers, params)
  File "/Library/Python/2.7/site-packages/btceapi/common.py", line 112, in makeRequest
    self.conn.request("POST", url, params, headers)
  File "/System/Library/Frameworks/Python.framework/Versions/2.7/lib/python2.7/httplib.py", line 973, in request
    self._send_request(method, url, body, headers)
  File "/System/Library/Frameworks/Python.framework/Versions/2.7/lib/python2.7/httplib.py", line 1001, in _send_request
    self.putrequest(method, url, **skips)
  File "/System/Library/Frameworks/Python.framework/Versions/2.7/lib/python2.7/httplib.py", line 871, in putrequest
    raise CannotSendRequest()
CannotSendRequest

--------------------------------------------------------------------------------
2014/01/18 20:14:29 - Error while retrieving btc_eur depth
Traceback (most recent call last):
  File "/Library/Python/2.7/site-packages/btcebot/bot.py", line 28, in _runBot
    asks, bids = btceapi.getDepth(p, conn)
  File "/Library/Python/2.7/site-packages/btceapi/public.py", line 67, in getDepth
    depth = connection.makeJSONRequest("/api/2/%s/depth" % pair)
  File "/Library/Python/2.7/site-packages/btceapi/common.py", line 118, in makeJSONRequest
    response = self.makeRequest(url, extra_headers, params)
  File "/Library/Python/2.7/site-packages/btceapi/common.py", line 112, in makeRequest
    self.conn.request("POST", url, params, headers)
  File "/System/Library/Frameworks/Python.framework/Versions/2.7/lib/python2.7/httplib.py", line 973, in request
    self._send_request(method, url, body, headers)
  File "/System/Library/Frameworks/Python.framework/Versions/2.7/lib/python2.7/httplib.py", line 1001, in _send_request
    self.putrequest(method, url, **skips)
  File "/System/Library/Frameworks/Python.framework/Versions/2.7/lib/python2.7/httplib.py", line 871, in putrequest
    raise CannotSendRequest()
CannotSendRequest

--------------------------------------------------------------------------------
2014/01/18 20:14:29 - Error while retrieving ltc_rur ticker
Traceback (most recent call last):
  File "/Library/Python/2.7/site-packages/btcebot/bot.py", line 100, in _ticker_loop
    response = btceapi.getTicker(p, conn)
  File "/Library/Python/2.7/site-packages/btceapi/public.py", line 50, in getTicker
    response = connection.makeJSONRequest("/api/2/%s/ticker" % pair)
  File "/Library/Python/2.7/site-packages/btceapi/common.py", line 118, in makeJSONRequest
    response = self.makeRequest(url, extra_headers, params)
  File "/Library/Python/2.7/site-packages/btceapi/common.py", line 112, in makeRequest
    self.conn.request("POST", url, params, headers)
  File "/System/Library/Frameworks/Python.framework/Versions/2.7/lib/python2.7/httplib.py", line 973, in request
    self._send_request(method, url, body, headers)
  File "/System/Library/Frameworks/Python.framework/Versions/2.7/lib/python2.7/httplib.py", line 1001, in _send_request
    self.putrequest(method, url, **skips)
  File "/System/Library/Frameworks/Python.framework/Versions/2.7/lib/python2.7/httplib.py", line 871, in putrequest
    raise CannotSendRequest()
CannotSendRequest

--------------------------------------------------------------------------------
2014/01/18 20:14:29 - Error while retrieving btc_rur depth
Traceback (most recent call last):
  File "/Library/Python/2.7/site-packages/btcebot/bot.py", line 28, in _runBot
    asks, bids = btceapi.getDepth(p, conn)
  File "/Library/Python/2.7/site-packages/btceapi/public.py", line 67, in getDepth
    depth = connection.makeJSONRequest("/api/2/%s/depth" % pair)
  File "/Library/Python/2.7/site-packages/btceapi/common.py", line 118, in makeJSONRequest
    response = self.makeRequest(url, extra_headers, params)
  File "/Library/Python/2.7/site-packages/btceapi/common.py", line 112, in makeRequest
    self.conn.request("POST", url, params, headers)
  File "/System/Library/Frameworks/Python.framework/Versions/2.7/lib/python2.7/httplib.py", line 973, in request
    self._send_request(method, url, body, headers)
  File "/System/Library/Frameworks/Python.framework/Versions/2.7/lib/python2.7/httplib.py", line 1001, in _send_request
    self.putrequest(method, url, **skips)
  File "/System/Library/Frameworks/Python.framework/Versions/2.7/lib/python2.7/httplib.py", line 871, in putrequest
    raise CannotSendRequest()
CannotSendRequest

--------------------------------------------------------------------------------
2014/01/18 20:14:29 - Error while retrieving ltc_usd ticker
Traceback (most recent call last):
  File "/Library/Python/2.7/site-packages/btcebot/bot.py", line 100, in _ticker_loop
    response = btceapi.getTicker(p, conn)
  File "/Library/Python/2.7/site-packages/btceapi/public.py", line 50, in getTicker
    response = connection.makeJSONRequest("/api/2/%s/ticker" % pair)
  File "/Library/Python/2.7/site-packages/btceapi/common.py", line 118, in makeJSONRequest
    response = self.makeRequest(url, extra_headers, params)
  File "/Library/Python/2.7/site-packages/btceapi/common.py", line 112, in makeRequest
    self.conn.request("POST", url, params, headers)
  File "/System/Library/Frameworks/Python.framework/Versions/2.7/lib/python2.7/httplib.py", line 973, in request
    self._send_request(method, url, body, headers)
  File "/System/Library/Frameworks/Python.framework/Versions/2.7/lib/python2.7/httplib.py", line 1001, in _send_request
    self.putrequest(method, url, **skips)
  File "/System/Library/Frameworks/Python.framework/Versions/2.7/lib/python2.7/httplib.py", line 871, in putrequest
    raise CannotSendRequest()
CannotSendRequest

--------------------------------------------------------------------------------
2014/01/18 20:14:29 - Error while retrieving ltc_eur trade history
Traceback (most recent call last):
  File "/Library/Python/2.7/site-packages/btcebot/bot.py", line 41, in _runBot
    trades = btceapi.getTradeHistory(p, conn)
  File "/Library/Python/2.7/site-packages/btceapi/public.py", line 111, in getTradeHistory
    history = connection.makeJSONRequest("/api/2/%s/trades" % pair)
  File "/Library/Python/2.7/site-packages/btceapi/common.py", line 118, in makeJSONRequest
    response = self.makeRequest(url, extra_headers, params)
  File "/Library/Python/2.7/site-packages/btceapi/common.py", line 112, in makeRequest
    self.conn.request("POST", url, params, headers)
  File "/System/Library/Frameworks/Python.framework/Versions/2.7/lib/python2.7/httplib.py", line 973, in request
    self._send_request(method, url, body, headers)
  File "/System/Library/Frameworks/Python.framework/Versions/2.7/lib/python2.7/httplib.py", line 1001, in _send_request
    self.putrequest(method, url, **skips)
  File "/System/Library/Frameworks/Python.framework/Versions/2.7/lib/python2.7/httplib.py", line 871, in putrequest
    raise CannotSendRequest()
CannotSendRequest

--------------------------------------------------------------------------------
2014/01/18 20:14:29 - Error while retrieving btc_eur ticker
Traceback (most recent call last):
  File "/Library/Python/2.7/site-packages/btcebot/bot.py", line 100, in _ticker_loop
    response = btceapi.getTicker(p, conn)
  File "/Library/Python/2.7/site-packages/btceapi/public.py", line 50, in getTicker
    response = connection.makeJSONRequest("/api/2/%s/ticker" % pair)
  File "/Library/Python/2.7/site-packages/btceapi/common.py", line 118, in makeJSONRequest
    response = self.makeRequest(url, extra_headers, params)
  File "/Library/Python/2.7/site-packages/btceapi/common.py", line 112, in makeRequest
    self.conn.request("POST", url, params, headers)
  File "/System/Library/Frameworks/Python.framework/Versions/2.7/lib/python2.7/httplib.py", line 973, in request
    self._send_request(method, url, body, headers)
  File "/System/Library/Frameworks/Python.framework/Versions/2.7/lib/python2.7/httplib.py", line 1001, in _send_request
    self.putrequest(method, url, **skips)
  File "/System/Library/Frameworks/Python.framework/Versions/2.7/lib/python2.7/httplib.py", line 871, in putrequest
    raise CannotSendRequest()
CannotSendRequest

--------------------------------------------------------------------------------
2014/01/18 20:14:29 - Error while retrieving btc_usd trade history
Traceback (most recent call last):
  File "/Library/Python/2.7/site-packages/btcebot/bot.py", line 41, in _runBot
    trades = btceapi.getTradeHistory(p, conn)
  File "/Library/Python/2.7/site-packages/btceapi/public.py", line 111, in getTradeHistory
    history = connection.makeJSONRequest("/api/2/%s/trades" % pair)
  File "/Library/Python/2.7/site-packages/btceapi/common.py", line 118, in makeJSONRequest
    response = self.makeRequest(url, extra_headers, params)
  File "/Library/Python/2.7/site-packages/btceapi/common.py", line 112, in makeRequest
    self.conn.request("POST", url, params, headers)
  File "/System/Library/Frameworks/Python.framework/Versions/2.7/lib/python2.7/httplib.py", line 973, in request
    self._send_request(method, url, body, headers)
  File "/System/Library/Frameworks/Python.framework/Versions/2.7/lib/python2.7/httplib.py", line 1001, in _send_request
    self.putrequest(method, url, **skips)
  File "/System/Library/Frameworks/Python.framework/Versions/2.7/lib/python2.7/httplib.py", line 871, in putrequest
    raise CannotSendRequest()
CannotSendRequest

--------------------------------------------------------------------------------
2014/01/18 20:14:29 - Error while retrieving btc_rur ticker
Traceback (most recent call last):
  File "/Library/Python/2.7/site-packages/btcebot/bot.py", line 100, in _ticker_loop
    response = btceapi.getTicker(p, conn)
  File "/Library/Python/2.7/site-packages/btceapi/public.py", line 50, in getTicker
    response = connection.makeJSONRequest("/api/2/%s/ticker" % pair)
  File "/Library/Python/2.7/site-packages/btceapi/common.py", line 118, in makeJSONRequest
    response = self.makeRequest(url, extra_headers, params)
  File "/Library/Python/2.7/site-packages/btceapi/common.py", line 112, in makeRequest
    self.conn.request("POST", url, params, headers)
  File "/System/Library/Frameworks/Python.framework/Versions/2.7/lib/python2.7/httplib.py", line 973, in request
    self._send_request(method, url, body, headers)
  File "/System/Library/Frameworks/Python.framework/Versions/2.7/lib/python2.7/httplib.py", line 1001, in _send_request
    self.putrequest(method, url, **skips)
  File "/System/Library/Frameworks/Python.framework/Versions/2.7/lib/python2.7/httplib.py", line 871, in putrequest
    raise CannotSendRequest()
CannotSendRequest

--------------------------------------------------------------------------------
2014/01/18 20:14:29 - Error while retrieving ltc_btc trade history
Traceback (most recent call last):
  File "/Library/Python/2.7/site-packages/btcebot/bot.py", line 41, in _runBot
    trades = btceapi.getTradeHistory(p, conn)
  File "/Library/Python/2.7/site-packages/btceapi/public.py", line 111, in getTradeHistory
    history = connection.makeJSONRequest("/api/2/%s/trades" % pair)
  File "/Library/Python/2.7/site-packages/btceapi/common.py", line 118, in makeJSONRequest
    response = self.makeRequest(url, extra_headers, params)
  File "/Library/Python/2.7/site-packages/btceapi/common.py", line 112, in makeRequest
    self.conn.request("POST", url, params, headers)
  File "/System/Library/Frameworks/Python.framework/Versions/2.7/lib/python2.7/httplib.py", line 973, in request
    self._send_request(method, url, body, headers)
  File "/System/Library/Frameworks/Python.framework/Versions/2.7/lib/python2.7/httplib.py", line 1001, in _send_request
    self.putrequest(method, url, **skips)
  File "/System/Library/Frameworks/Python.framework/Versions/2.7/lib/python2.7/httplib.py", line 871, in putrequest
    raise CannotSendRequest()
CannotSendRequest

--------------------------------------------------------------------------------
2014/01/18 20:14:29 - Error while retrieving ltc_rur trade history
Traceback (most recent call last):
  File "/Library/Python/2.7/site-packages/btcebot/bot.py", line 41, in _runBot
    trades = btceapi.getTradeHistory(p, conn)
  File "/Library/Python/2.7/site-packages/btceapi/public.py", line 111, in getTradeHistory
    history = connection.makeJSONRequest("/api/2/%s/trades" % pair)
  File "/Library/Python/2.7/site-packages/btceapi/common.py", line 118, in makeJSONRequest
    response = self.makeRequest(url, extra_headers, params)
  File "/Library/Python/2.7/site-packages/btceapi/common.py", line 112, in makeRequest
    self.conn.request("POST", url, params, headers)
  File "/System/Library/Frameworks/Python.framework/Versions/2.7/lib/python2.7/httplib.py", line 973, in request
    self._send_request(method, url, body, headers)
  File "/System/Library/Frameworks/Python.framework/Versions/2.7/lib/python2.7/httplib.py", line 1001, in _send_request
    self.putrequest(method, url, **skips)
  File "/System/Library/Frameworks/Python.framework/Versions/2.7/lib/python2.7/httplib.py", line 871, in putrequest
    raise CannotSendRequest()
CannotSendRequest

--------------------------------------------------------------------------------
2014/01/18 20:14:29 - Error while retrieving ltc_usd trade history
Traceback (most recent call last):
  File "/Library/Python/2.7/site-packages/btcebot/bot.py", line 41, in _runBot
    trades = btceapi.getTradeHistory(p, conn)
  File "/Library/Python/2.7/site-packages/btceapi/public.py", line 111, in getTradeHistory
    history = connection.makeJSONRequest("/api/2/%s/trades" % pair)
  File "/Library/Python/2.7/site-packages/btceapi/common.py", line 118, in makeJSONRequest
    response = self.makeRequest(url, extra_headers, params)
  File "/Library/Python/2.7/site-packages/btceapi/common.py", line 112, in makeRequest
    self.conn.request("POST", url, params, headers)
  File "/System/Library/Frameworks/Python.framework/Versions/2.7/lib/python2.7/httplib.py", line 973, in request
    self._send_request(method, url, body, headers)
  File "/System/Library/Frameworks/Python.framework/Versions/2.7/lib/python2.7/httplib.py", line 1001, in _send_request
    self.putrequest(method, url, **skips)
  File "/System/Library/Frameworks/Python.framework/Versions/2.7/lib/python2.7/httplib.py", line 871, in putrequest
    raise CannotSendRequest()
CannotSendRequest

--------------------------------------------------------------------------------
2014/01/18 20:14:29 - Error while retrieving btc_eur trade history
Traceback (most recent call last):
  File "/Library/Python/2.7/site-packages/btcebot/bot.py", line 41, in _runBot
    trades = btceapi.getTradeHistory(p, conn)
  File "/Library/Python/2.7/site-packages/btceapi/public.py", line 111, in getTradeHistory
    history = connection.makeJSONRequest("/api/2/%s/trades" % pair)
  File "/Library/Python/2.7/site-packages/btceapi/common.py", line 118, in makeJSONRequest
    response = self.makeRequest(url, extra_headers, params)
  File "/Library/Python/2.7/site-packages/btceapi/common.py", line 112, in makeRequest
    self.conn.request("POST", url, params, headers)
  File "/System/Library/Frameworks/Python.framework/Versions/2.7/lib/python2.7/httplib.py", line 973, in request
    self._send_request(method, url, body, headers)
  File "/System/Library/Frameworks/Python.framework/Versions/2.7/lib/python2.7/httplib.py", line 1001, in _send_request
    self.putrequest(method, url, **skips)
  File "/System/Library/Frameworks/Python.framework/Versions/2.7/lib/python2.7/httplib.py", line 871, in putrequest
    raise CannotSendRequest()
CannotSendRequest

--------------------------------------------------------------------------------
2014/01/18 20:14:29 - Error while retrieving btc_rur trade history
Traceback (most recent call last):
  File "/Library/Python/2.7/site-packages/btcebot/bot.py", line 41, in _runBot
    trades = btceapi.getTradeHistory(p, conn)
  File "/Library/Python/2.7/site-packages/btceapi/public.py", line 111, in getTradeHistory
    history = connection.makeJSONRequest("/api/2/%s/trades" % pair)
  File "/Library/Python/2.7/site-packages/btceapi/common.py", line 118, in makeJSONRequest
    response = self.makeRequest(url, extra_headers, params)
  File "/Library/Python/2.7/site-packages/btceapi/common.py", line 112, in makeRequest
    self.conn.request("POST", url, params, headers)
  File "/System/Library/Frameworks/Python.framework/Versions/2.7/lib/python2.7/httplib.py", line 973, in request
    self._send_request(method, url, body, headers)
  File "/System/Library/Frameworks/Python.framework/Versions/2.7/lib/python2.7/httplib.py", line 1001, in _send_request
    self.putrequest(method, url, **skips)
  File "/System/Library/Frameworks/Python.framework/Versions/2.7/lib/python2.7/httplib.py", line 871, in putrequest
    raise CannotSendRequest()
CannotSendRequest

--------------------------------------------------------------------------------
2014/01/18 20:14:41 - Error in handler <bound method TradeBot.onNewDepth of <__main__.TradeBot object at 0x10cdfb350>> for ltc_eur depth
Traceback (most recent call last):
  File "/Library/Python/2.7/site-packages/btcebot/bot.py", line 52, in _runBot
    handler(t, p, asks, bids)
  File "/Users/afansky/dev/code/bitcoin_bot/trade-bot/tradebot/tradebot.py", line 23, in onNewDepth
    self.analyzer.analyze(t, pair)
  File "/Users/afansky/dev/code/bitcoin_bot/trade-bot/tradebot/analysis/analysis.py", line 24, in analyze
    df = create_data_frame(ticks)
  File "/Users/afansky/dev/code/bitcoin_bot/trade-bot/tradebot/analysis/analysis.py", line 44, in create_data_frame
    index.append(tick[0])
KeyError: 0

--------------------------------------------------------------------------------
2014/01/18 20:14:45 - Error in handler <bound method TradeBot.onNewDepth of <__main__.TradeBot object at 0x10cdfb350>> for btc_usd depth
Traceback (most recent call last):
  File "/Library/Python/2.7/site-packages/btcebot/bot.py", line 52, in _runBot
    handler(t, p, asks, bids)
  File "/Users/afansky/dev/code/bitcoin_bot/trade-bot/tradebot/tradebot.py", line 23, in onNewDepth
    self.analyzer.analyze(t, pair)
  File "/Users/afansky/dev/code/bitcoin_bot/trade-bot/tradebot/analysis/analysis.py", line 24, in analyze
    df = create_data_frame(ticks)
  File "/Users/afansky/dev/code/bitcoin_bot/trade-bot/tradebot/analysis/analysis.py", line 44, in create_data_frame
    index.append(tick[0])
KeyError: 0

--------------------------------------------------------------------------------
